Workbook

Sheet LED (8%)
A1: Công ty CP Bóng Đèn Phích Nước Rạng Đông
A2: Chi Nhánh Tiền Giang
A3: BẢNG BÁO GIÁ ĐÈN LED - THUẾ VAT 8%
A4: STT | B4: Sản phẩm | C4: ĐVT | D4: Giá bán cấp 1 | F4: Giá bán lẻ
D5: Chưa VAT | E5: Có VAT | F5: Chưa VAT | G5: Có VAT
B6: LED Downlight
A7: 1 | B7: Đèn LED Downlight AT06 76/3W 6500K SS | C7: đ/c | D7: 47000 | E7: =D7*1.08 -> 50760 | F7: 94444 | G7: =F7*1.08 -> 101999.52 | I7: =VLOOKUP(B7,'GIÁ 1.4'!$D:$F,2,0) -> 47000 | J7: =D7-I7 -> 0 | K7: =VLOOKUP(B7,'GIÁ 1.4'!$D:$F,3,0) -> 94444 | L7: =F7-K7 -> 0
A8: 2 | B8: Đèn LED Downlight AT06 90/5W 6500K SS | C8: đ/c | D8: 48500 | E8: =D8*1.08 -> 52380 | F8: 97037 | G8: =F8*1.08 -> 104799.96 | I8: =VLOOKUP(B8,'GIÁ 1.4'!$D:$F,2,0) -> 48500 | J8: =D8-I8 -> 0 | K8: =VLOOKUP(B8,'GIÁ 1.4'!$D:$F,3,0) -> 97037 | L8: =F8-K8 -> 0
A9: 3 | B9: Đèn LED Downlight AT06.V2 90/5W 6500K | C9: đ/c | D9: 48500 | E9: =D9*1.08 -> 52380 | F9: 97037 | G9: =F9*1.08 -> 104799.96 | I9: =VLOOKUP(B9,'GIÁ 1.4'!$D:$F,2,0) -> 48500 | J9: =D9-I9 -> 0 | K9: =VLOOKUP(B9,'GIÁ 1.4'!$D:$F,3,0) -> 97037 | L9: =F9-K9 -> 0
A10: 4 | B10: Đèn LED Downlight AT06 90/7W 6500K SS | C10: đ/c | D10: 57400 | E10: =D10*1.08 -> 61992 | F10: 114815 | G10: =F10*1.08 -> 124000.2 | I10: =VLOOKUP(B10,'GIÁ 1.4'!$D:$F,2,0) -> 57400 | J10: =D10-I10 -> 0 | K10: =VLOOKUP(B10,'GIÁ 1.4'!$D:$F,3,0) -> 114815 | L10: =F10-K10 -> 0
A11: 5 | B11: Đèn LED Downlight AT06.V2 90/7W 6500K | C11: đ/c | D11: 57400 | E11: =D11*1.08 -> 61992 | F11: 114815 | G11: =F11*1.08 -> 124000.2 | I11: =VLOOKUP(B11,'GIÁ 1.4'!$D:$F,2,0) -> 57400 | J11: =D11-I11 -> 0 | K11: =VLOOKUP(B11,'GIÁ 1.4'!$D:$F,3,0) -> 114815 | L11: =F11-K11 -> 0
A12: 6 | B12: Đèn LED Downlight AT06 110/7W 6500K SS | C12: đ/c | D12: 69000 | E12: =D12*1.08 -> 74520 | F12: 137963 | G12: =F12*1.08 -> 149000.04 | I12: =VLOOKUP(B12,'GIÁ 1.4'!$D:$F,2,0) -> 69000 | J12: =D12-I12 -> 0 | K12: =VLOOKUP(B12,'GIÁ 1.4'!$D:$F,3,0) -> 137963 | L12: =F12-K12 -> 0
A13: 7 | B13: Đèn LED Downlight AT06 110/9W 6500K SS | C13: đ/c | D13: 81200 | E13: =D13*1.08 -> 87696 | F13: 162037 | G13: =F13*1.08 -> 174999.96 | I13: =VLOOKUP(B13,'GIÁ 1.4'!$D:$F,2,0) -> 81200 | J13: =D13-I13 -> 0 | K13: =VLOOKUP(B13,'GIÁ 1.4'!$D:$F,3,0) -> 162037 | L13: =F13-K13 -> 0
A14: 8 | B14: Đèn LED Downlight AT06.V2 110/9W 6500K | C14: đ/c | D14: 81200 | E14: =D14*1.08 -> 87696 | F14: 162037 | G14: =F14*1.08 -> 174999.96 | I14: =VLOOKUP(B14,'GIÁ 1.4'!$D:$F,2,0) -> 81200 | J14: =D14-I14 -> 0 | K14: =VLOOKUP(B14,'GIÁ 1.4'!$D:$F,3,0) -> 162037 | L14: =F14-K14 -> 0
A15: 9 | B15: Đèn LED Downlight AT10 90/7W 6500K (G) | C15: đ/c | D15: 70100 | E15: =D15*1.08 -> 75708 | F15: 139815 | G15: =F15*1.08 -> 151000.2 | I15: =VLOOKUP(B15,'GIÁ 1.4'!$D:$F,2,0) -> 70100 | J15: =D15-I15 -> 0 | K15: =VLOOKUP(B15,'GIÁ 1.4'!$D:$F,3,0) -> 139815 | L15: =F15-K15 -> 0
A16: 10 | B16: Đèn LED Downlight AT10 90/7W 6500K | C16: đ/c | D16: 70100 | E16: =D16*1.08 -> 75708 | F16: 139815 | G16: =F16*1.08 -> 151000.2 | I16: =VLOOKUP(B16,'GIÁ 1.4'!$D:$F,2,0) -> 70100 | J16: =D16-I16 -> 0 | K16: =VLOOKUP(B16,'GIÁ 1.4'!$D:$F,3,0) -> 139815 | L16: =F16-K16 -> 0
A17: 11 | B17: Đèn LED Downlight AT10 110/9W 6500K (G) | C17: đ/c | D17: 83800 | E17: =D17*1.08 -> 90504 | F17: 167593 | G17: =F17*1.08 -> 181000.44 | I17: =VLOOKUP(B17,'GIÁ 1.4'!$D:$F,2,0) -> 83800 | J17: =D17-I17 -> 0 | K17: =VLOOKUP(B17,'GIÁ 1.4'!$D:$F,3,0) -> 167593 | L17: =F17-K17 -> 0
A18: 12 | B18: Đèn LED Downlight AT11 90/7W 6500K SS | C18: đ/c | D18: 54000 | E18: =D18*1.08 -> 58320 | F18: 97273 | G18: =F18*1.08 -> 105054.84 | I18: =VLOOKUP(B18,'GIÁ 1.4'!$D:$F,2,0) -> 54000 | J18: =D18-I18 -> 0 | K18: =VLOOKUP(B18,'GIÁ 1.4'!$D:$F,3,0) -> 97273 | L18: =F18-K18 -> 0
... A94: 88 | B94: Đèn LED Downlight AT06.V3 110/9W 6500K | C94: đ/c | D94: 65000 | E94: =D94*1.08 -> 70200 | F94: 129630 | G94: =F94*1.08 -> 140000.4 | I94: =VLOOKUP(B94,'GIÁ 1.4'!$D:$F,2,0) -> 65000 | J94: =D94-I94 -> 0 | K94: =VLOOKUP(B94,'GIÁ 1.4'!$D:$F,3,0) -> 129630 | L94: =F94-K94 -> 0
A95: 89 | B95: Đèn LED Downlight AT04 90/8W 6500K | C95: đ/c | D95: 70100 | E95: =D95*1.08 -> 75708 | F95: 139815 | G95: 171000 | I95: =VLOOKUP(B95,'GIÁ 1.4'!$D:$F,2,0) -> 70100 | J95: =D95-I95 -> 0 | K95: =VLOOKUP(B95,'GIÁ 1.4'!$D:$F,3,0) -> 139815 | L95: =F95-K95 -> 0
A96: 90 | B96: Đèn LED Downlight AT04 90/10W 6500K | C96: đ/c | D96: 72700 | E96: =D96*1.08 -> 78516 | F96: 145370 | G96: 182000 | I96: =VLOOKUP(B96,'GIÁ 1.4'!$D:$F,2,0) -> 72700 | J96: =D96-I96 -> 0 | K96: =VLOOKUP(B96,'GIÁ 1.4'!$D:$F,3,0) -> 145370 | L96: =F96-K96 -> 0
A97: 91 | B97: Đèn LED Downlight AT04 110/10W 6500K | C97: đ/c | D97: 83800 | E97: =D97*1.08 -> 90504 | F97: 167593 | G97: 203000 | I97: =VLOOKUP(B97,'GIÁ 1.4'!$D:$F,2,0) -> 83800 | J97: =D97-I97 -> 0 | K97: =VLOOKUP(B97,'GIÁ 1.4'!$D:$F,3,0) -> 167593 | L97: =F97-K97 -> 0
A98: 92 | B98: Đèn LED Downlight AT10 90/8W 6500K | C98: đ/c | D98: 70100 | E98: =D98*1.08 -> 75708 | F98: 139815 | G98: 171000 | I98: =VLOOKUP(B98,'GIÁ 1.4'!$D:$F,2,0) -> 70100 | J98: =D98-I98 -> 0 | K98: =VLOOKUP(B98,'GIÁ 1.4'!$D:$F,3,0) -> 139815 | L98: =F98-K98 -> 0
A99: 93 | B99: Đèn LED Downlight AT10 90/8W 6500K (G) | C99: đ/c | D99: 70100 | E99: =D99*1.08 -> 75708 | F99: 139815 | G99: 171000 | I99: =VLOOKUP(B99,'GIÁ 1.4'!$D:$F,2,0) -> 70100 | J99: =D99-I99 -> 0 | K99: =VLOOKUP(B99,'GIÁ 1.4'!$D:$F,3,0) -> 139815 | L99: =F99-K99 -> 0
A100: 94 | B100: Đèn LED Downlight AT10 110/10W 6500K | C100: đ/c | D100: 83800 | E100: =D100*1.08 -> 90504 | F100: 167593 | G100: 203000 | I100: =VLOOKUP(B100,'GIÁ 1.4'!$D:$F,2,0) -> 83800 | J100: =D100-I100 -> 0 | K100: =VLOOKUP(B100,'GIÁ 1.4'!$D:$F,3,0) -> 167593 | L100: =F100-K100 -> 0
A101: 95 | B101: Đèn LED Downlight AT10 110/10W 6500K (G) | C101: đ/c | D101: 83800 | E101: =D101*1.08 -> 90504 | F101: 167593 | G101: 203000 | I101: =VLOOKUP(B101,'GIÁ 1.4'!$D:$F,2,0) -> 83800 | J101: =D101-I101 -> 0 | K101: =VLOOKUP(B101,'GIÁ 1.4'!$D:$F,3,0) -> 167593 | L101: =F101-K101 -> 0
A102: 96 | B102: Đèn LED Downlight đổi màu AT10 90/8W | C102: đ/c | D102: 79500 | E102: =D102*1.08 -> 85860 | F102: 159259 | G102: 198000 | I102: =VLOOKUP(B102,'GIÁ 1.4'!$D:$F,2,0) -> 79500 | J102: =D102-I102 -> 0 | K102: =VLOOKUP(B102,'GIÁ 1.4'!$D:$F,3,0) -> 159259 | L102: =F102-K102 -> 0
A103: 97 | B103: Đèn LED Downlight đổi màu AT10 90/8W (G) | C103: đ/c | D103: 79500 | E103: =D103*1.08 -> 85860 | F103: 159259 | G103: 198000 | I103: =VLOOKUP(B103,'GIÁ 1.4'!$D:$F,2,0) -> 79500 | J103: =D103-I103 -> 0 | K103: =VLOOKUP(B103,'GIÁ 1.4'!$D:$F,3,0) -> 159259 | L103: =F103-K103 -> 0
A104: 98 | B104: Đèn LED Downlight đổi màu AT10 90/10W | C104: đ/c | D104: 83200 | E104: =D104*1.08 -> 89856 | F104: 166667 | G104: 205000 | I104: =VLOOKUP(B104,'GIÁ 1.4'!$D:$F,2,0) -> 83200 | J104: =D104-I104 -> 0 | K104: =VLOOKUP(B104,'GIÁ 1.4'!$D:$F,3,0) -> 166667 | L104: =F104-K104 -> 0
A105: 99 | B105: Đèn LED Downlight đổi màu AT10 90/10W (G) | C105: đ/c | D105: 83200 | E105: =D105*1.08 -> 89856 | F105: 166667 | G105: 205000 | I105: =VLOOKUP(B105,'GIÁ 1.4'!$D:$F,2,0) -> 83200 | J105: =D105-I105 -> 0 | K105: =VLOOKUP(B105,'GIÁ 1.4'!$D:$F,3,0) -> 166667 | L105: =F105-K105 -> 0
A106: 100 | B106: Đèn LED Downlight đổi màu AT10 110/10W | C106: đ/c | D106: 94600 | E106: =D106*1.08 -> 102168 | F106: 188889 | G106: 236000 | I106: =VLOOKUP(B106,'GIÁ 1.4'!$D:$F,2,0) -> 94600 | J106: =D106-I106 -> 0 | K106: =VLOOKUP(B106,'GIÁ 1.4'!$D:$F,3,0) -> 188889 | L106: =F106-K106 -> 0
A107: 101 | B107: Đèn LED Downlight đổi màu AT10 110/10W (G) | C107: đ/c | D107: 94600 | E107: =D107*1.08 -> 102168 | F107: 188889 | G107: 236000 | I107: =VLOOKUP(B107,'GIÁ 1.4'!$D:$F,2,0) -> 94600 | J107: =D107-I107 -> 0 | K107: =VLOOKUP(B107,'GIÁ 1.4'!$D:$F,3,0) -> 188889 | L107: =F107-K107 -> 0
A108: 102 | B108: Đèn LED Downlight AT56 90/8W 6500K | C108: đ/c | D108: 70100 | E108: 85320 | F108: 139815 | G108: 171000 | I108: =VLOOKUP(B108,'GIÁ 1.4'!$D:$F,2,0) -> 70100 | J108: =D108-I108 -> 0 | K108: =VLOOKUP(B108,'GIÁ 1.4'!$D:$F,3,0) -> 139815 | L108: =F108-K108 -> 0
A109: 103 | B109: Đèn LED Downlight AT56 90/8W 6500K (G) | C109: đ/c | D109: 70100 | E109: 85320 | F109: 139815 | G109: 171000 | I109: =VLOOKUP(B109,'GIÁ 1.4'!$D:$F,2,0) -> 70100 | J109: =D109-I109 -> 0 | K109: =VLOOKUP(B109,'GIÁ 1.4'!$D:$F,3,0) -> 139815 | L109: =F109-K109 -> 0
A110: 104 | B110: Đèn LED Downlight AT56 90/10W 6500K | C110: đ/c | D110: 72700 | E110: 90720 | F110: 145370 | G110: 182000 | I110: =VLOOKUP(B110,'GIÁ 1.4'!$D:$F,2,0) -> 72700 | J110: =D110-I110 -> 0 | K110: =VLOOKUP(B110,'GIÁ 1.4'!$D:$F,3,0) -> 145370 | L110: =F110-K110 -> 0
A111: 105 | B111: Đèn LED Downlight AT56 90/10W 6500K (G) | C111: đ/c | D111: 72700 | E111: 90720 | F111: 145370 | G111: 182000 | I111: =VLOOKUP(B111,'GIÁ 1.4'!$D:$F,2,0) -> 72700 | J111: =D111-I111 -> 0 | K111: =VLOOKUP(B111,'GIÁ 1.4'!$D:$F,3,0) -> 145370 | L111: =F111-K111 -> 0
A112: 106 | B112: Đèn LED Downlight AT56 110/10W 6500K | C112: đ/c | D112: 83800 | E112: 101520 | F112: 167593 | G112: 203000 | I112: =VLOOKUP(B112,'GIÁ 1.4'!$D:$F,2,0) -> 83800 | J112: =D112-I112 -> 0 | K112: =VLOOKUP(B112,'GIÁ 1.4'!$D:$F,3,0) -> 167593 | L112: =F112-K112 -> 0
A113: 107 | B113: Đèn LED Downlight AT56 110/10W 6500K (G) | C113: đ/c | D113: 83800 | E113: 101520 | F113: 167593 | G113: 203000 | I113: =VLOOKUP(B113,'GIÁ 1.4'!$D:$F,2,0) -> 83800 | J113: =D113-I113 -> 0 | K113: =VLOOKUP(B113,'GIÁ 1.4'!$D:$F,3,0) -> 167593 | L113: =F113-K113 -> 0
A114: 108 | B114: Đèn LED Downlight đổi màu AT56 90/8W | C114: đ/c | D114: 79500 | E114: 99360 | F114: 159259 | G114: 198000 | I114: =VLOOKUP(B114,'GIÁ 1.4'!$D:$F,2,0) -> 79500 | J114: =D114-I114 -> 0 | K114: =VLOOKUP(B114,'GIÁ 1.4'!$D:$F,3,0) -> 159259 | L114: =F114-K114 -> 0
A115: 109 | B115: Đèn LED Downlight đổi màu AT56 90/8W (G) | C115: đ/c | D115: 79500 | E115: 99360 | F115: 159259 | G115: 198000 | I115: =VLOOKUP(B115,'GIÁ 1.4'!$D:$F,2,0) -> 79500 | J115: =D115-I115 -> 0 | K115: =VLOOKUP(B115,'GIÁ 1.4'!$D:$F,3,0) -> 159259 | L115: =F115-K115 -> 0
...

Sheet GIÁ 1.4
D1: 1 | E1: 2 | F1: 3
A2: # | B2: Tên chủng loại | C2: Mã Hàng hóa | D2: Mô tả hàng hóa | E2: P0003-Giá cấp 1 MN | F2: P0018-Giá lẻ niêm yết
A3: 1 | B3: Bộ đèn LED | C3: 00000266 | D3: Bộ đèn LED Tube T8 M9/22Wx1.GO 5000K | E3: 0 | F3: 0
A4: 2 | B4: Bộ đèn LED | C4: LED00005508 | D4: Bộ đèn LED TUBE T8 M9/18Wx2 Trắng S(110V) | E4: 0 | F4: 0
A5: 3 | B5: Bộ đèn LED | C5: LED00006000 | D5: Bộ đèn LED Tube T8 M9/18Wx1 3000K | E5: 0 | F5: 0
A6: 4 | B6: Bộ đèn LED | C6: LED00012349 | D6: Bộ đèn LED Tube T8 CA01/18Wx2 6500K SS | E6: 503000 | F6: 1006000
A7: 5 | B7: Bộ đèn LED | C7: LED00012752 | D7: Bộ đèn LED Tube T5 LT03 600/8W 6500K SS | E7: 58600 | F7: 103704
A8: 6 | B8: Bộ đèn LED | C8: LED00014194 | D8: Bộ đèn LED CSLH/20Wx1 6500K SS | E8: 0 | F8: 645370
A9: 7 | B9: Bộ đèn LED | C9: LED00014195 | D9: Bộ đèn LED Tube T8 CSLH/20Wx2 6500K SS | E9: 550000 | F9: 882407
A10: 8 | B10: Bộ đèn LED | C10: LED00019550 | D10: LED LUMINAIRE FS T8 12Wx4-M6-6500K(XK) | E10: 0 | F10: 0
A11: 9 | B11: Bộ đèn LED | C11: LED00025158 | D11: Bộ LED Tube T8 M11/10Wx1 6500K SS-CT | E11: 99000 | F11: 198148
A12: 10 | B12: Bộ đèn LED | C12: LED00025465 | D12: Bộ đèn LED M26 600/18W 6500K | E12: 84900 | F12: 179630
A13: 11 | B13: Bộ đèn LED | C13: LED00026383 | D13: Bộ đèn LED Tube T8 M11/20Wx1.DA 6500K SS | E13: 0 | F13: 0
A14: 12 | B14: Bộ đèn LED | C14: LED00026507 | D14: Bộ đèn LED chống nổ CN01 1200/36W.DA 6500K | E14: 0 | F14: 2170000
... A2363: 2361 | B2363: LED công suất cao | C2363: LED00072862 | D2363: Đèn LED Highbay HB02 430/150W 6500K | E2363: 1319000 | F2363: 2637963
A2364: 2362 | B2364: LED công suất cao | C2364: LED00073352 | E2364: 1645000 | F2364: 3289815
A2365: 2363 | B2365: LED công suất cao | C2365: LED00073635 | D2365: Đèn LED chiếu sáng đường CSD10 80W.NEMA 4000K | E2365: 0 | F2365: 5900000
A2366: 2364 | B2366: LED công suất cao | C2366: LED00074456 | D2366: Đèn LED Highbay GDXL1074 3FT 320W 4000K (Yankon) | E2366: 0 | F2366: 0
A2367: 2365 | B2367: LED công suất cao | C2367: LED00074474 | D2367: Đèn LED chiếu sáng đường NLMT CSD08.SL 100W 4000K | E2367: 0 | F2367: 0
A2368: 2366 | B2368: LED công suất cao | C2368: LED00075185 | D2368: Tấm Solar Poly crystalline CP03.SL.RAD 300W.V2 (TP)-CT | E2368: 0 | F2368: 0
A2369: 2367 | B2369: LED công suất cao | C2369: LED00079607 | D2369: Đèn LED Chiếu pha CP12 50W 6500K | E2369: 213000 | F2369: 425926
A2370: 2368 | B2370: LED công suất cao | C2370: LED00079707 | D2370: Đèn chiếu sáng đường NLMT CSD08.SL.HB 120W 5000K | E2370: 0 | F2370: 0
A2371: 2369 | B2371: LED công suất cao | C2371: LED00080145 | D2371: Đèn LED NLMT NX.SL.RAD 300W 6500K | E2371: 1390000 | F2371: 2779630
A2372: 2370 | B2372: LED công suất cao | C2372: LED00080217 | D2372: Đèn LED Chiếu pha CP12 100W 6500K | E2372: 523000 | F2372: 1046296
A2373: 2371 | B2373: LED công suất cao | C2373: LED00082850 | D2373: Đèn LED Chiếu pha CP12 10W 3000K | E2373: 96800 | F2373: 193519
A2374: 2372 | B2374: LED công suất cao | C2374: LED00082852 | D2374: Đèn LED Chiếu pha CP12 30W 3000K | E2374: 155000 | F2374: 310185
A2375: 2373 | B2375: LED công suất cao | C2375: LED00083164 | D2375: Đèn LED Chiếu pha CPT02 6W.APG 3000K (20D) | E2375: 0 | F2375: 0
A2376: 2374 | B2376: LED Downlight + Panel tròn | C2376: LED00005241 | D2376: Đèn Led Downlight AT03 76/3W 6500K | E2376: 38700 | F2376: 66667
... A7768: 7766 | B7768: Vỏ phích & phụ tùng phích | C7768: PHN00017614 | D7768: Vỏ phích Inox 1.0L-MOR | E7768: 0 | F7768: 0
